<?xml version="1.0" ?>
<robot name="wheel">

<material name="silver">
  <color rgba="0.700 0.700 0.700 1.000"/>
</material>

<link name="base_link">
  <inertial>
    <origin xyz="1.0581425375182096 -6.871472135417827e-05 1.1419314828993112" rpy="0 0 0"/>
    <mass value="16381.629180344515"/>
    <inertia ixx="6061.708588598449" iyy="5579.829327521315" izz="6044.194468342095" ixy="0.014612218140540145" iyz="0.9150934065047782" ixz="421.01583283182845"/>
  </inertial>
  <visual>
    <origin xyz="0 0 0" rpy="0 0 0"/>
    <geometry>
      <mesh filename="meshes_wheel/base_link.stl" scale="0.001 0.001 0.001"/>
    </geometry>
    <material name="silver"/>
    <material/>
  </visual>
  <collision>
    <origin xyz="0 0 0" rpy="0 0 0"/>
    <geometry>
      <mesh filename="meshes_wheel/base_link.stl" scale="0.001 0.001 0.001"/>
    </geometry>
  </collision>
</link>

<link name="WheelRightFront_1_11">
  <inertial>
    <origin xyz="-5.599182362203692e-08 -0.20008732119846462 -4.2109491071862237e-07" rpy="0 0 0"/>
    <mass value="7402.977610753146"/>
    <inertia ixx="1530.5000639588834" iyy="2828.173363515183" izz="1530.5000697293654" ixy="8.214701665565372e-07" iyz="-2.3495304048992693e-06" ixz="1.3469580153468996e-06"/>
  </inertial>
  <visual>
    <origin xyz="-1.615577 1.130962 -0.848462" rpy="0 0 0"/>
    <geometry>
      <mesh filename="meshes_wheel/WheelRightFront_1_11.stl" scale="0.001 0.001 0.001"/>
    </geometry>
    <material name="silver"/>
    <material/>
  </visual>
  <collision>
    <origin xyz="-1.615577 1.130962 -0.848462" rpy="0 0 0"/>
    <geometry>
      <mesh filename="meshes_wheel/WheelRightFront_1_11.stl" scale="0.001 0.001 0.001"/>
    </geometry>
  </collision>
</link>

<link name="WheelLeftFront_1_11">
  <inertial>
    <origin xyz="-5.6982715879172474e-08 0.200088297952149 -4.2463636995559995e-07" rpy="0 0 0"/>
    <mass value="7402.977962014108"/>
    <inertia ixx="1530.500162622233" iyy="2828.1735978176293" izz="1530.5002209135564" ixy="-2.06546246772632e-07" iyz="1.5095793060027063e-06" ixz="-1.0986537745338865e-05"/>
  </inertial>
  <visual>
    <origin xyz="-1.615577 -1.130961 -0.848462" rpy="0 0 0"/>
    <geometry>
      <mesh filename="meshes_wheel/WheelLeftFront_1_11.stl" scale="0.001 0.001 0.001"/>
    </geometry>
    <material name="silver"/>
    <material/>
  </visual>
  <collision>
    <origin xyz="-1.615577 -1.130961 -0.848462" rpy="0 0 0"/>
    <geometry>
      <mesh filename="meshes_wheel/WheelLeftFront_1_11.stl" scale="0.001 0.001 0.001"/>
    </geometry>
  </collision>
</link>

<link name="WheelLeftBack_1_11">
  <inertial>
    <origin xyz="3.7676631858829523e-07 0.200088297952149 1.8010952862468343e-07" rpy="0 0 0"/>
    <mass value="7402.977962014084"/>
    <inertia ixx="1530.5001626221165" iyy="2828.173597817655" izz="1530.5002209134436" ixy="-2.0662082533817738e-07" iyz="1.509564754087478e-06" ixz="-1.0986534107360058e-05"/>
  </inertial>
  <visual>
    <origin xyz="1.615385 -1.130961 -0.849" rpy="0 0 0"/>
    <geometry>
      <mesh filename="meshes_wheel/WheelLeftBack_1_11.stl" scale="0.001 0.001 0.001"/>
    </geometry>
    <material name="silver"/>
    <material/>
  </visual>
  <collision>
    <origin xyz="1.615385 -1.130961 -0.849" rpy="0 0 0"/>
    <geometry>
      <mesh filename="meshes_wheel/WheelLeftBack_1_11.stl" scale="0.001 0.001 0.001"/>
    </geometry>
  </collision>
</link>

<link name="WheelRightBack_1_11">
  <inertial>
    <origin xyz="3.773292645004034e-07 -0.2000873211984635 1.842443995148102e-07" rpy="0 0 0"/>
    <mass value="7402.9776107531425"/>
    <inertia ixx="1530.5000636721925" iyy="2828.1733635152887" izz="1530.5000700160708" ixy="1.216940290760249e-06" iyz="-2.1711803128710017e-06" ixz="2.7891292120330036e-07"/>
  </inertial>
  <visual>
    <origin xyz="1.615385 1.130962 -0.849" rpy="0 0 0"/>
    <geometry>
      <mesh filename="meshes_wheel/WheelRightBack_1_11.stl" scale="0.001 0.001 0.001"/>
    </geometry>
    <material name="silver"/>
    <material/>
  </visual>
  <collision>
    <origin xyz="1.615385 1.130962 -0.849" rpy="0 0 0"/>
    <geometry>
      <mesh filename="meshes_wheel/WheelRightBack_1_11.stl" scale="0.001 0.001 0.001"/>
    </geometry>
  </collision>
</link>

<link name="RearBody_1_11">
  <inertial>
    <origin xyz="-1.734747014815235 0.0038129194313433873 0.7437630852359651" rpy="0 0 0"/>
    <mass value="47802.82120502296"/>
    <inertia ixx="27071.58799513738" iyy="60502.85949801651" izz="48239.29169088573" ixy="-50.31802200145802" iyz="-163.92864383031628" ixz="-6207.0560117212735"/>
  </inertial>
  <visual>
    <origin xyz="0.0 -0.0 -0.744615" rpy="0 0 0"/>
    <geometry>
      <mesh filename="meshes_wheel/RearBody_1_11.stl" scale="0.001 0.001 0.001"/>
    </geometry>
    <material name="silver"/>
    <material/>
  </visual>
  <collision>
    <origin xyz="0.0 -0.0 -0.744615" rpy="0 0 0"/>
    <geometry>
      <mesh filename="meshes_wheel/RearBody_1_11.stl" scale="0.001 0.001 0.001"/>
    </geometry>
  </collision>
</link>

<joint name="Rev6" type="continuous">
  <origin xyz="1.615577 -1.130962 0.848462" rpy="0 0 0"/>
  <parent link="base_link"/>
  <child link="WheelRightFront_1_11"/>
  <axis xyz="-0.0 1.0 0.0"/>
</joint>
<transmission name="Rev6_tran">
  <type>transmission_interface/SimpleTransmission</type>
  <joint name="Rev6">
    <hardwareInterface>PositionJointInterface</hardwareInterface>
  </joint>
  <actuator name="Rev6_actr">
    <hardwareInterface>PositionJointInterface</hardwareInterface>
    <mechanicalReduction>1</mechanicalReduction>
  </actuator>
</transmission>

<joint name="Rev7" type="continuous">
  <origin xyz="1.615577 1.130961 0.848462" rpy="0 0 0"/>
  <parent link="base_link"/>
  <child link="WheelLeftFront_1_11"/>
  <axis xyz="0.0 -1.0 -0.0"/>
</joint>
<transmission name="Rev7_tran">
  <type>transmission_interface/SimpleTransmission</type>
  <joint name="Rev7">
    <hardwareInterface>PositionJointInterface</hardwareInterface>
  </joint>
  <actuator name="Rev7_actr">
    <hardwareInterface>PositionJointInterface</hardwareInterface>
    <mechanicalReduction>1</mechanicalReduction>
  </actuator>
</transmission>

<joint name="Rev8" type="continuous">
  <origin xyz="-1.615385 1.130961 0.104385" rpy="0 0 0"/>
  <parent link="RearBody_1_11"/>
  <child link="WheelLeftBack_1_11"/>
  <axis xyz="-0.0 1.0 0.0"/>
</joint>
<transmission name="Rev8_tran">
  <type>transmission_interface/SimpleTransmission</type>
  <joint name="Rev8">
    <hardwareInterface>PositionJointInterface</hardwareInterface>
  </joint>
  <actuator name="Rev8_actr">
    <hardwareInterface>PositionJointInterface</hardwareInterface>
    <mechanicalReduction>1</mechanicalReduction>
  </actuator>
</transmission>

<joint name="Rev9" type="continuous">
  <origin xyz="-1.615385 -1.130962 0.104385" rpy="0 0 0"/>
  <parent link="RearBody_1_11"/>
  <child link="WheelRightBack_1_11"/>
  <axis xyz="-0.0 1.0 0.0"/>
</joint>
<transmission name="Rev9_tran">
  <type>transmission_interface/SimpleTransmission</type>
  <joint name="Rev9">
    <hardwareInterface>PositionJointInterface</hardwareInterface>
  </joint>
  <actuator name="Rev9_actr">
    <hardwareInterface>PositionJointInterface</hardwareInterface>
    <mechanicalReduction>1</mechanicalReduction>
  </actuator>
</transmission>

<joint name="Rev10" type="revolute">
  <origin xyz="0.0 0.0 0.744615" rpy="0 0 0"/>
  <parent link="base_link"/>
  <child link="RearBody_1_11"/>
  <axis xyz="-0.0 0.0 1.0"/>
  <limit upper="0.1" lower="-0.1" effort="100" velocity="100"/>
</joint>
<transmission name="Rev10_tran">
  <type>transmission_interface/SimpleTransmission</type>
  <joint name="Rev10">
    <hardwareInterface>PositionJointInterface</hardwareInterface>
  </joint>
  <actuator name="Rev10_actr">
    <hardwareInterface>PositionJointInterface</hardwareInterface>
    <mechanicalReduction>1</mechanicalReduction>
  </actuator>
</transmission>

</robot>
